Workbook
Name SelectedTeam: Team_Dashboard!$C$2

Sheet tbl_L1_Raw
A1: Match ID | B1: Date | C1: Home Team | D1: Away Team | E1: Home xG | F1: Away xG | G1: Home Goals | H1: Away Goals | I1: xG Difference (Home - Away | J1: Goal difference | K1: Total xG | L1: Total Goals | M1: xG Overperformance (Home) | N1: xG Overperformance (Away) | O1: Result | P1: Match ID count
A2: L1_0001 | B2: 46249 | C2: Barnsley | D2: Bromley | E2: 1.32 | F2: 1.42 | G2: 0 | H2: 1 | I2: =IF(E2="","",E2-F2) -> -0.1 | J2: =IF(G2="","",G2-H2) -> -1 | K2: =IF(E2="","",E2+F2) -> 2.74 | L2: =IF(G2="","",G2+H2) -> 1 | M2: =IF(G2="","",G2-E2) -> -1.32 | N2: =IF(H2="","",H2-F2) -> -0.42 | O2: =IF(G2="","",IF(G2>H2,"Home Win",IF(G2<H2,"Away Win","Draw"))) -> Away Win | P2: =COUNTIF(Homematches[Match ID],Homematches[[#This Row],[Match ID]]) -> 1
A3: L1_0002 | B3: 46249 | C3: Blackpool | D3: Wycombe Wanderers | E3: 2.37 | F3: 1.29 | G3: 1 | H3: 1 | I3: =IF(E3="","",E3-F3) -> 1.08 | J3: =IF(G3="","",G3-H3) -> 0 | K3: =IF(E3="","",E3+F3) -> 3.66 | L3: =IF(G3="","",G3+H3) -> 2 | M3: =IF(G3="","",G3-E3) -> -1.37 | N3: =IF(H3="","",H3-F3) -> -0.29 | O3: =IF(G3="","",IF(G3>H3,"Home Win",IF(G3<H3,"Away Win","Draw"))) -> Draw | P3: =COUNTIF(Homematches[Match ID],Homematches[[#This Row],[Match ID]]) -> 1
A4: L1_0003 | B4: 46249 | C4: Bradford City | D4: Peterborough United | E4: 1.97 | F4: 1.11 | G4: 2 | H4: 0 | I4: =IF(E4="","",E4-F4) -> 0.86 | J4: =IF(G4="","",G4-H4) -> 2 | K4: =IF(E4="","",E4+F4) -> 3.08 | L4: =IF(G4="","",G4+H4) -> 2 | M4: =IF(G4="","",G4-E4) -> 0.03 | N4: =IF(H4="","",H4-F4) -> -1.11 | O4: =IF(G4="","",IF(G4>H4,"Home Win",IF(G4<H4,"Away Win","Draw"))) -> Home Win | P4: =COUNTIF(Homematches[Match ID],Homematches[[#This Row],[Match ID]]) -> 1
A5: L1_0004 | B5: 46249 | C5: Burton Albion | D5: Stevenage | E5: 0.94 | F5: 0.53 | G5: 1 | H5: 1 | I5: =IF(E5="","",E5-F5) -> 0.41 | J5: =IF(G5="","",G5-H5) -> 0 | K5: =IF(E5="","",E5+F5) -> 1.47 | L5: =IF(G5="","",G5+H5) -> 2 | M5: =IF(G5="","",G5-E5) -> 0.06 | N5: =IF(H5="","",H5-F5) -> 0.47 | O5: =IF(G5="","",IF(G5>H5,"Home Win",IF(G5<H5,"Away Win","Draw"))) -> Draw | P5: =COUNTIF(Homematches[Match ID],Homematches[[#This Row],[Match ID]]) -> 1
A6: L1_0005 | B6: 46249 | C6: Cambridge United | D6: Wigan Athletic | E6: 1.74 | F6: 2.2 | G6: 3 | H6: 2 | I6: =IF(E6="","",E6-F6) -> -0.46 | J6: =IF(G6="","",G6-H6) -> 1 | K6: =IF(E6="","",E6+F6) -> 3.94 | L6: =IF(G6="","",G6+H6) -> 5 | M6: =IF(G6="","",G6-E6) -> 1.26 | N6: =IF(H6="","",H6-F6) -> -0.2 | O6: =IF(G6="","",IF(G6>H6,"Home Win",IF(G6<H6,"Away Win","Draw"))) -> Home Win | P6: =COUNTIF(Homematches[Match ID],Homematches[[#This Row],[Match ID]]) -> 1
A7: L1_0006 | B7: 46249 | C7: Huddersfield Town | D7: AFC Wimbledon | E7: 1.24 | F7: 0.38 | G7: 3 | H7: 0 | I7: =IF(E7="","",E7-F7) -> 0.86 | J7: =IF(G7="","",G7-H7) -> 3 | K7: =IF(E7="","",E7+F7) -> 1.62 | L7: =IF(G7="","",G7+H7) -> 3 | M7: =IF(G7="","",G7-E7) -> 1.76 | N7: =IF(H7="","",H7-F7) -> -0.38 | O7: =IF(G7="","",IF(G7>H7,"Home Win",IF(G7<H7,"Away Win","Draw"))) -> Home Win | P7: =COUNTIF(Homematches[Match ID],Homematches[[#This Row],[Match ID]]) -> 1
A8: L1_0007 | B8: 46249 | C8: Leyton Orient | D8: Sheffield Wednesday | E8: 1.38 | F8: 2.84 | G8: 1 | H8: 2 | I8: =IF(E8="","",E8-F8) -> -1.46 | J8: =IF(G8="","",G8-H8) -> -1 | K8: =IF(E8="","",E8+F8) -> 4.22 | L8: =IF(G8="","",G8+H8) -> 3 | M8: =IF(G8="","",G8-E8) -> -0.38 | N8: =IF(H8="","",H8-F8) -> -0.84 | O8: =IF(G8="","",IF(G8>H8,"Home Win",IF(G8<H8,"Away Win","Draw"))) -> Away Win | P8: =COUNTIF(Homematches[Match ID],Homematches[[#This Row],[Match ID]]) -> 1
A9: L1_0008 | B9: 46249 | C9: Mansfield Town | D9: Doncaster Rovers | E9: 1.44 | F9: 1.06 | G9: 2 | H9: 1 | I9: =IF(E9="","",E9-F9) -> 0.38 | J9: =IF(G9="","",G9-H9) -> 1 | K9: =IF(E9="","",E9+F9) -> 2.5 | L9: =IF(G9="","",G9+H9) -> 3 | M9: =IF(G9="","",G9-E9) -> 0.56 | N9: =IF(H9="","",H9-F9) -> -0.06 | O9: =IF(G9="","",IF(G9>H9,"Home Win",IF(G9<H9,"Away Win","Draw"))) -> Home Win | P9: =COUNTIF(Homematches[Match ID],Homematches[[#This Row],[Match ID]]) -> 1
A10: L1_0009 | B10: 46249 | C10: Notts County | D10: Leicester City | E10: 2.18 | F10: 0.74 | G10: 1 | H10: 1 | I10: =IF(E10="","",E10-F10) -> 1.44 | J10: =IF(G10="","",G10-H10) -> 0 | K10: =IF(E10="","",E10+F10) -> 2.92 | L10: =IF(G10="","",G10+H10) -> 2 | M10: =IF(G10="","",G10-E10) -> -1.18 | N10: =IF(H10="","",H10-F10) -> 0.26 | O10: =IF(G10="","",IF(G10>H10,"Home Win",IF(G10<H10,"Away Win","Draw"))) -> Draw | P10: =COUNTIF(Homematches[Match ID],Homematches[[#This Row],[Match ID]]) -> 1
A11: L1_0010 | B11: 46249 | C11: Oxford United | D11: Milton Keynes Dons | E11: 1.83 | F11: 2.2 | G11: 2 | H11: 2 | I11: =IF(E11="","",E11-F11) -> -0.37 | J11: =IF(G11="","",G11-H11) -> 0 | K11: =IF(E11="","",E11+F11) -> 4.03 | L11: =IF(G11="","",G11+H11) -> 4 | M11: =IF(G11="","",G11-E11) -> 0.17 | N11: =IF(H11="","",H11-F11) -> -0.2 | O11: =IF(G11="","",IF(G11>H11,"Home Win",IF(G11<H11,"Away Win","Draw"))) -> Draw | P11: =COUNTIF(Homematches[Match ID],Homematches[[#This Row],[Match ID]]) -> 1
A12: L1_0011 | B12: 46249 | C12: Plymouth Argyle | D12: Stockport County | E12: 0.92 | F12: 1.81 | G12: 1 | H12: 3 | I12: =IF(E12="","",E12-F12) -> -0.89 | J12: =IF(G12="","",G12-H12) -> -2 | K12: =IF(E12="","",E12+F12) -> 2.73 | L12: =IF(G12="","",G12+H12) -> 4 | M12: =IF(G12="","",G12-E12) -> 0.08 | N12: =IF(H12="","",H12-F12) -> 1.19 | O12: =IF(G12="","",IF(G12>H12,"Home Win",IF(G12<H12,"Away Win","Draw"))) -> Away Win | P12: =COUNTIF(Homematches[Match ID],Homematches[[#This Row],[Match ID]]) -> 1
A13: L1_0012 | B13: 46249 | C13: Reading | D13: Luton Town | E13: 1.61 | F13: 1.65 | G13: 3 | H13: 4 | I13: =IF(E13="","",E13-F13) -> -0.04 | J13: =IF(G13="","",G13-H13) -> -1 | K13: =IF(E13="","",E13+F13) -> 3.26 | L13: =IF(G13="","",G13+H13) -> 7 | M13: =IF(G13="","",G13-E13) -> 1.39 | N13: =IF(H13="","",H13-F13) -> 2.35 | O13: =IF(G13="","",IF(G13>H13,"Home Win",IF(G13<H13,"Away Win","Draw"))) -> Away Win | P13: =COUNTIF(Homematches[Match ID],Homematches[[#This Row],[Match ID]]) -> 1
... A60: L1_0059 | B60: 46272 | C60: Bromley | D60: AFC Wimbledon | E60: 0.55 | F60: 1.22 | G60: 0 | H60: 2 | I60: =IF(E60="","",E60-F60) -> -0.67 | J60: =IF(G60="","",G60-H60) -> -2 | K60: =IF(E60="","",E60+F60) -> 1.77 | L60: =IF(G60="","",G60+H60) -> 2 | M60: =IF(G60="","",G60-E60) -> -0.55 | N60: =IF(H60="","",H60-F60) -> 0.78 | O60: =IF(G60="","",IF(G60>H60,"Home Win",IF(G60<H60,"Away Win","Draw"))) -> Away Win | P60: =COUNTIF(Homematches[Match ID],Homematches[[#This Row],[Match ID]]) -> 1
A61: L1_0060 | B61: 46273 | C61: Oxford United | D61: Reading | I61: =IF(E61="","",E61-F61) | J61: =IF(G61="","",G61-H61) | K61: =IF(E61="","",E61+F61) | L61: =IF(G61="","",G61+H61) | M61: =IF(G61="","",G61-E61) | N61: =IF(H61="","",H61-F61) | O61: =IF(G61="","",IF(G61>H61,"Home Win",IF(G61<H61,"Away Win","Draw"))) | P61: =COUNTIF(Homematches[Match ID],Homematches[[#This Row],[Match ID]]) -> 1
A62: L1_0061 | B62: 46275 | C62: Stevenage | D62: Luton Town | E62: 1.31 | F62: 0.89 | G62: 2 | H62: 1 | I62: =IF(E62="","",E62-F62) -> 0.42 | J62: =IF(G62="","",G62-H62) -> 1 | K62: =IF(E62="","",E62+F62) -> 2.2 | L62: =IF(G62="","",G62+H62) -> 3 | M62: =IF(G62="","",G62-E62) -> 0.69 | N62: =IF(H62="","",H62-F62) -> 0.11 | O62: =IF(G62="","",IF(G62>H62,"Home Win",IF(G62<H62,"Away Win","Draw"))) -> Home Win | P62: =COUNTIF(Homematches[Match ID],Homematches[[#This Row],[Match ID]]) -> 1
A63: L1_0062 | B63: 46277 | C63: AFC Wimbledon | D63: Doncaster Rovers | E63: 0.81 | F63: 2.41 | G63: 1 | H63: 0 | I63: =IF(E63="","",E63-F63) -> -1.6 | J63: =IF(G63="","",G63-H63) -> 1 | K63: =IF(E63="","",E63+F63) -> 3.22 | L63: =IF(G63="","",G63+H63) -> 1 | M63: =IF(G63="","",G63-E63) -> 0.19 | N63: =IF(H63="","",H63-F63) -> -2.41 | O63: =IF(G63="","",IF(G63>H63,"Home Win",IF(G63<H63,"Away Win","Draw"))) -> Home Win | P63: =COUNTIF(Homematches[Match ID],Homematches[[#This Row],[Match ID]]) -> 1
A64: L1_0063 | B64: 46277 | C64: Blackpool | D64: Bromley | E64: 1.17 | F64: 1.38 | G64: 2 | H64: 2 | I64: =IF(E64="","",E64-F64) -> -0.21 | J64: =IF(G64="","",G64-H64) -> 0 | K64: =IF(E64="","",E64+F64) -> 2.55 | L64: =IF(G64="","",G64+H64) -> 4 | M64: =IF(G64="","",G64-E64) -> 0.83 | N64: =IF(H64="","",H64-F64) -> 0.62 | O64: =IF(G64="","",IF(G64>H64,"Home Win",IF(G64<H64,"Away Win","Draw"))) -> Draw | P64: =COUNTIF(Homematches[Match ID],Homematches[[#This Row],[Match ID]]) -> 1
A65: L1_0064 | B65: 46277 | C65: Cambridge United | D65: Reading | E65: 0.94 | F65: 1.99 | G65: 2 | H65: 1 | I65: =IF(E65="","",E65-F65) -> -1.05 | J65: =IF(G65="","",G65-H65) -> 1 | K65: =IF(E65="","",E65+F65) -> 2.93 | L65: =IF(G65="","",G65+H65) -> 3 | M65: =IF(G65="","",G65-E65) -> 1.06 | N65: =IF(H65="","",H65-F65) -> -0.99 | O65: =IF(G65="","",IF(G65>H65,"Home Win",IF(G65<H65,"Away Win","Draw"))) -> Home Win | P65: =COUNTIF(Homematches[Match ID],Homematches[[#This Row],[Match ID]]) -> 1
A66: L1_0065 | B66: 46277 | C66: Leyton Orient | D66: Wycombe Wanderers | E66: 0.88 | F66: 1.16 | G66: 2 | H66: 3 | I66: =IF(E66="","",E66-F66) -> -0.28 | J66: =IF(G66="","",G66-H66) -> -1 | K66: =IF(E66="","",E66+F66) -> 2.04 | L66: =IF(G66="","",G66+H66) -> 5 | M66: =IF(G66="","",G66-E66) -> 1.12 | N66: =IF(H66="","",H66-F66) -> 1.84 | O66: =IF(G66="","",IF(G66>H66,"Home Win",IF(G66<H66,"Away Win","Draw"))) -> Away Win | P66: =COUNTIF(Homematches[Match ID],Homematches[[#This Row],[Match ID]]) -> 1
A67: L1_0066 | B67: 46277 | C67: Mansfield Town | D67: Huddersfield Town | E67: 0.86 | F67: 1.36 | G67: 0 | H67: 0 | I67: =IF(E67="","",E67-F67) -> -0.5 | J67: =IF(G67="","",G67-H67) -> 0 | K67: =IF(E67="","",E67+F67) -> 2.22 | L67: =IF(G67="","",G67+H67) -> 0 | M67: =IF(G67="","",G67-E67) -> -0.86 | N67: =IF(H67="","",H67-F67) -> -1.36 | O67: =IF(G67="","",IF(G67>H67,"Home Win",IF(G67<H67,"Away Win","Draw"))) -> Draw | P67: =COUNTIF(Homematches[Match ID],Homematches[[#This Row],[Match ID]]) -> 1
A68: L1_0067 | B68: 46277 | C68: Milton Keynes Dons | D68: Peterborough United | E68: 1.24 | F68: 1.21 | G68: 1 | H68: 1 | I68: =IF(E68="","",E68-F68) -> 0.03 | J68: =IF(G68="","",G68-H68) -> 0 | K68: =IF(E68="","",E68+F68) -> 2.45 | L68: =IF(G68="","",G68+H68) -> 2 | M68: =IF(G68="","",G68-E68) -> -0.24 | N68: =IF(H68="","",H68-F68) -> -0.21 | O68: =IF(G68="","",IF(G68>H68,"Home Win",IF(G68<H68,"Away Win","Draw"))) -> Draw | P68: =COUNTIF(Homematches[Match ID],Homematches[[#This Row],[Match ID]]) -> 1
A69: L1_0068 | B69: 46277 | C69: Notts County | D69: Bradford City | E69: 0.49 | F69: 0.5 | G69: 0 | H69: 1 | I69: =IF(E69="","",E69-F69) -> -0.01 | J69: =IF(G69="","",G69-H69) -> -1 | K69: =IF(E69="","",E69+F69) -> 0.99 | L69: =IF(G69="","",G69+H69) -> 1 | M69: =IF(G69="","",G69-E69) -> -0.49 | N69: =IF(H69="","",H69-F69) -> 0.5 | O69: =IF(G69="","",IF(G69>H69,"Home Win",IF(G69<H69,"Away Win","Draw"))) -> Away Win | P69: =COUNTIF(Homematches[Match ID],Homematches[[#This Row],[Match ID]]) -> 1
A70: L1_0069 | B70: 46277 | C70: Oxford United | D70: Burton Albion | E70: 1.21 | F70: 0.47 | G70: 3 | H70: 0 | I70: =IF(E70="","",E70-F70) -> 0.74 | J70: =IF(G70="","",G70-H70) -> 3 | K70: =IF(E70="","",E70+F70) -> 1.68 | L70: =IF(G70="","",G70+H70) -> 3 | M70: =IF(G70="","",G70-E70) -> 1.79 | N70: =IF(H70="","",H70-F70) -> -0.47 | O70: =IF(G70="","",IF(G70>H70,"Home Win",IF(G70<H70,"Away Win","Draw"))) -> Home Win | P70: =COUNTIF(Homematches[Match ID],Homematches[[#This Row],[Match ID]]) -> 1
A71: L1_0070 | B71: 46277 | C71: Plymouth Argyle | D71: Barnsley | E71: 0.99 | F71: 0.77 | G71: 3 | H71: 0 | I71: =IF(E71="","",E71-F71) -> 0.22 | J71: =IF(G71="","",G71-H71) -> 3 | K71: =IF(E71="","",E71+F71) -> 1.76 | L71: =IF(G71="","",G71+H71) -> 3 | M71: =IF(G71="","",G71-E71) -> 2.01 | N71: =IF(H71="","",H71-F71) -> -0.77 | O71: =IF(G71="","",IF(G71>H71,"Home Win",IF(G71<H71,"Away Win","Draw"))) -> Home Win | P71: =COUNTIF(Homematches[Match ID],Homematches[[#This Row],[Match ID]]) -> 1
A72: L1_0071 | B72: 46277 | C72: Sheffield Wednesday | D72: Wigan Athletic | E72: 0.82 | F72: 1.59 | G72: 0 | H72: 0 | I72: =IF(E72="","",E72-F72) -> -0.77 | J72: =IF(G72="","",G72-H72) -> 0 | K72: =IF(E72="","",E72+F72) -> 2.41 | L72: =IF(G72="","",G72+H72) -> 0 | M72: =IF(G72="","",G72-E72) -> -0.82 | N72: =IF(H72="","",H72-F72) -> -1.59 | O72: =IF(G72="","",IF(G72>H72,"Home Win",IF(G72<H72,"Away Win","Draw"))) -> Draw | P72: =COUNTIF(Homematches[Match ID],Homematches[[#This Row],[Match ID]]) -> 1
A73: L1_0072 | B73: 46277 | C73: Stockport County | D73: Leicester City | E73: 2.29 | F73: 1.21 | G73: 3 | H73: 4 | I73: =IF(E73="","",E73-F73) -> 1.08 | J73: =IF(G73="","",G73-H73) -> -1 | K73: =IF(E73="","",E73+F73) -> 3.5 | L73: =IF(G73="","",G73+H73) -> 7 | M73: =IF(G73="","",G73-E73) -> 0.71 | N73: =IF(H73="","",H73-F73) -> 2.79 | O73: =IF(G73="","",IF(G73>H73,"Home Win",IF(G73<H73,"Away Win","Draw"))) -> Away Win | P73: =COUNTIF(Homematches[Match ID],Homematches[[#This Row],[Match ID]]) -> 1
A74: L1_0073 | B74: 46282 | C74: AFC Wimbledon | D74: Milton Keynes Dons | I74: =IF(E74="","",E74-F74) | J74: =IF(G74="","",G74-H74) | K74: =IF(E74="","",E74+F74) | L74: =IF(G74="","",G74+H74) | M74: =IF(G74="","",G74-E74) | N74: =IF(H74="","",H74-F74) | O74: =IF(G74="","",IF(G74>H74,"Home Win",IF(G74<H74,"Away Win","Draw"))) | P74: =COUNTIF(Homematches[Match ID],Homematches[[#This Row],[Match ID]]) -> 1
A75: L1_0074 | B75: 46284 | C75: Barnsley | D75: Leicester City | I75: =IF(E75="","",E75-F75) | J75: =IF(G75="","",G75-H75) | K75: =IF(E75="","",E75+F75) | L75: =IF(G75="","",G75+H75) | M75: =IF(G75="","",G75-E75) | N75: =IF(H75="","",H75-F75) | O75: =IF(G75="","",IF(G75>H75,"Home Win",IF(G75<H75,"Away Win","Draw"))) | P75: =COUNTIF(Homematches[Match ID],Homematches[[#This Row],[Match ID]]) -> 1
A76: L1_0075 | B76: 46284 | C76: Blackpool | D76: Plymouth Argyle | I76: =IF(E76="","",E76-F76) | J76: =IF(G76="","",G76-H76) | K76: =IF(E76="","",E76+F76) | L76: =IF(G76="","",G76+H76) | M76: =IF(G76="","",G76-E76) | N76: =IF(H76="","",H76-F76) | O76: =IF(G76="","",IF(G76>H76,"Home Win",IF(G76<H76,"Away Win","Draw"))) | P76: =COUNTIF(Homematches[Match ID],Homematches[[#This Row],[Match ID]]) -> 1
A77: L1_0076 | B77: 46284 | C77: Bromley | D77: Huddersfield Town | I77: =IF(E77="","",E77-F77) | J77: =IF(G77="","",G77-H77) | K77: =IF(E77="","",E77+F77) | L77: =IF(G77="","",G77+H77) | M77: =IF(G77="","",G77-E77) | N77: =IF(H77="","",H77-F77) | O77: =IF(G77="","",IF(G77>H77,"Home Win",IF(G77<H77,"Away Win","Draw"))) | P77: =COUNTIF(Homematches[Match ID],Homematches[[#This Row],[Match ID]]) -> 1
A78: L1_0077 | B78: 46284 | C78: Burton Albion | D78: Mansfield Town | I78: =IF(E78="","",E78-F78) | J78: =IF(G78="","",G78-H78) | K78: =IF(E78="","",E78+F78) | L78: =IF(G78="","",G78+H78) | M78: =IF(G78="","",G78-E78) | N78: =IF(H78="","",H78-F78) | O78: =IF(G78="","",IF(G78>H78,"Home Win",IF(G78<H78,"Away Win","Draw"))) | P78: =COUNTIF(Homematches[Match ID],Homematches[[#This Row],[Match ID]]) -> 1
A79: L1_0078 | B79: 46284 | C79: Leyton Orient | D79: Stevenage | I79: =IF(E79="","",E79-F79) | J79: =IF(G79="","",G79-H79) | K79: =IF(E79="","",E79+F79) | L79: =IF(G79="","",G79+H79) | M79: =IF(G79="","",G79-E79) | N79: =IF(H79="","",H79-F79) | O79: =IF(G79="","",IF(G79>H79,"Home Win",IF(G79<H79,"Away Win","Draw"))) | P79: =COUNTIF(Homematches[Match ID],Homematches[[#This Row],[Match ID]]) -> 1
A80: L1_0079 | B80: 46284 | C80: Luton Town | D80: Bradford City | I80: =IF(E80="","",E80-F80) | J80: =IF(G80="","",G80-H80) | K80: =IF(E80="","",E80+F80) | L80: =IF(G80="","",G80+H80) | M80: =IF(G80="","",G80-E80) | N80: =IF(H80="","",H80-F80) | O80: =IF(G80="","",IF(G80>H80,"Home Win",IF(G80<H80,"Away Win","Draw"))) | P80: =COUNTIF(Homematches[Match ID],Homematches[[#This Row],[Match ID]]) -> 1
A81: L1_0080 | B81: 46284 | C81: Oxford United | D81: Cambridge United | I81: =IF(E81="","",E81-F81) | J81: =IF(G81="","",G81-H81) | K81: =IF(E81="","",E81+F81) | L81: =IF(G81="","",G81+H81) | M81: =IF(G81="","",G81-E81) | N81: =IF(H81="","",H81-F81) | O81: =IF(G81="","",IF(G81>H81,"Home Win",IF(G81<H81,"Away Win","Draw"))) | P81: =COUNTIF(Homematches[Match ID],Homematches[[#This Row],[Match ID]]) -> 1
A82: L1_0081 | B82: 46284 | C82: Peterborough United | D82: Doncaster Rovers | I82: =IF(E82="","",E82-F82) | J82: =IF(G82="","",G82-H82) | K82: =IF(E82="","",E82+F82) | L82: =IF(G82="","",G82+H82) | M82: =IF(G82="","",G82-E82) | N82: =IF(H82="","",H82-F82) | O82: =IF(G82="","",IF(G82>H82,"Home Win",IF(G82<H82,"Away Win","Draw"))) | P82: =COUNTIF(Homematches[Match ID],Homematches[[#This Row],[Match ID]]) -> 1
A83: L1_0082 | B83: 46284 | C83: Reading | D83: Notts County | I83: =IF(E83="","",E83-F83) | J83: =IF(G83="","",G83-H83) | K83: =IF(E83="","",E83+F83) | L83: =IF(G83="","",G83+H83) | M83: =IF(G83="","",G83-E83) | N83: =IF(H83="","",H83-F83) | O83: =IF(G83="","",IF(G83>H83,"Home Win",IF(G83<H83,"Away Win","Draw"))) | P83: =COUNTIF(Homematches[Match ID],Homematches[[#This Row],[Match ID]]) -> 1
A84: L1_0083 | B84: 46284 | C84: Sheffield Wednesday | D84: Stockport County | I84: =IF(E84="","",E84-F84) | J84: =IF(G84="","",G84-H84) | K84: =IF(E84="","",E84+F84) | L84: =IF(G84="","",G84+H84) | M84: =IF(G84="","",G84-E84) | N84: =IF(H84="","",H84-F84) | O84: =IF(G84="","",IF(G84>H84,"Home Win",IF(G84<H84,"Away Win","Draw"))) | P84: =COUNTIF(Homematches[Match ID],Homematches[[#This Row],[Match ID]]) -> 1
A85: L1_0084 | B85: 46284 | C85: Wigan Athletic | D85: Wycombe Wanderers | I85: =IF(E85="","",E85-F85) | J85: =IF(G85="","",G85-H85) | K85: =IF(E85="","",E85+F85) | L85: =IF(G85="","",G85+H85) | M85: =IF(G85="","",G85-E85) | N85: =IF(H85="","",H85-F85) | O85: =IF(G85="","",IF(G85>H85,"Home Win",IF(G85<H85,"Away Win","Draw"))) | P85: =COUNTIF(Homematches[Match ID],Homematches[[#This Row],[Match ID]]) -> 1
... A553: L1_0552 | B553: 46515 | C553: Wycombe Wanderers | D553: Barnsley | I553: =IF(E553="","",E553-F553) | J553: =IF(G553="","",G553-H553) | K553: =IF(E553="","",E553+F553) | L553: =IF(G553="","",G553+H553) | M553: =IF(G553="","",G553-E553) | N553: =IF(H553="","",H553-F553) | O553: =IF(G553="","",IF(G553>H553,"Home Win",IF(G553<H553,"Away Win","Draw"))) | P553: =COUNTIF(Homematches[Match ID],Homematches[[#This Row],[Match ID]]) -> 1

Sheet Home Sheet
A1: Match ID | B1: Date | C1: Team | D1: Opponent | E1: Team xG | F1: Opponent xG | G1: Team Goals | H1: Opponent Goals | I1: Total xG | J1: Total Goals | K1: Match ID count | L1: Venue
A2: L1_0001 | B2: 46249 | C2: Barnsley | D2: Bromley | E2: 1.32 | F2: 1.42 | G2: 0 | H2: 1 | I2: 2.74 | J2: 1 | K2: 1 | L2: Home
A3: L1_0002 | B3: 46249 | C3: Blackpool | D3: Wycombe Wanderers | E3: 2.37 | F3: 1.29 | G3: 1 | H3: 1 | I3: 3.66 | J3: 2 | K3: 1 | L3: Home
A4: L1_0003 | B4: 46249 | C4: Bradford City | D4: Peterborough United | E4: 1.97 | F4: 1.11 | G4: 2 | H4: 0 | I4: 3.08 | J4: 2 | K4: 1 | L4: Home
A5: L1_0004 | B5: 46249 | C5: Burton Albion | D5: Stevenage | E5: 0.94 | F5: 0.53 | G5: 1 | H5: 1 | I5: 1.47 | J5: 2 | K5: 1 | L5: Home
A6: L1_0005 | B6: 46249 | C6: Cambridge United | D6: Wigan Athletic | E6: 1.74 | F6: 2.2 | G6: 3 | H6: 2 | I6: 3.94 | J6: 5 | K6: 1 | L6: Home
A7: L1_0006 | B7: 46249 | C7: Huddersfield Town | D7: AFC Wimbledon | E7: 1.24 | F7: 0.38 | G7: 3 | H7: 0 | I7: 1.62 | J7: 3 | K7: 1 | L7: Home
A8: L1_0007 | B8: 46249 | C8: Leyton Orient | D8: Sheffield Wednesday | E8: 1.38 | F8: 2.84 | G8: 1 | H8: 2 | I8: 4.22 | J8: 3 | K8: 1 | L8: Home
A9: L1_0008 | B9: 46249 | C9: Mansfield Town | D9: Doncaster Rovers | E9: 1.44 | F9: 1.06 | G9: 2 | H9: 1 | I9: 2.5 | J9: 3 | K9: 1 | L9: Home
A10: L1_0009 | B10: 46249 | C10: Notts County | D10: Leicester City | E10: 2.18 | F10: 0.74 | G10: 1 | H10: 1 | I10: 2.92 | J10: 2 | K10: 1 | L10: Home
A11: L1_0010 | B11: 46249 | C11: Oxford United | D11: Milton Keynes Dons | E11: 1.83 | F11: 2.2 | G11: 2 | H11: 2 | I11: 4.03 | J11: 4 | K11: 1 | L11: Home
A12: L1_0011 | B12: 46249 | C12: Plymouth Argyle | D12: Stockport County | E12: 0.92 | F12: 1.81 | G12: 1 | H12: 3 | I12: 2.73 | J12: 4 | K12: 1 | L12: Home
A13: L1_0012 | B13: 46249 | C13: Reading | D13: Luton Town | E13: 1.61 | F13: 1.65 | G13: 3 | H13: 4 | I13: 3.26 | J13: 7 | K13: 1 | L13: Home
... A60: L1_0059 | B60: 46272 | C60: Bromley | D60: AFC Wimbledon | E60: 0.55 | F60: 1.22 | G60: 0 | H60: 2 | I60: 1.77 | J60: 2 | K60: 1 | L60: Home
A61: L1_0060 | B61: 46273 | C61: Oxford United | D61: Reading | K61: 1 | L61: Home
A62: L1_0061 | B62: 46275 | C62: Stevenage | D62: Luton Town | E62: 1.31 | F62: 0.89 | G62: 2 | H62: 1 | I62: 2.2 | J62: 3 | K62: 1 | L62: Home
A63: L1_0062 | B63: 46277 | C63: AFC Wimbledon | D63: Doncaster Rovers | E63: 0.81 | F63: 2.41 | G63: 1 | H63: 0 | I63: 3.22 | J63: 1 | K63: 1 | L63: Home
A64: L1_0063 | B64: 46277 | C64: Blackpool | D64: Bromley | E64: 1.17 | F64: 1.38 | G64: 2 | H64: 2 | I64: 2.55 | J64: 4 | K64: 1 | L64: Home
A65: L1_0064 | B65: 46277 | C65: Cambridge United | D65: Reading | E65: 0.94 | F65: 1.99 | G65: 2 | H65: 1 | I65: 2.93 | J65: 3 | K65: 1 | L65: Home
A66: L1_0065 | B66: 46277 | C66: Leyton Orient | D66: Wycombe Wanderers | E66: 0.88 | F66: 1.16 | G66: 2 | H66: 3 | I66: 2.04 | J66: 5 | K66: 1 | L66: Home
A67: L1_0066 | B67: 46277 | C67: Mansfield Town | D67: Huddersfield Town | E67: 0.86 | F67: 1.36 | G67: 0 | H67: 0 | I67: 2.22 | J67: 0 | K67: 1 | L67: Home
A68: L1_0067 | B68: 46277 | C68: Milton Keynes Dons | D68: Peterborough United | E68: 1.24 | F68: 1.21 | G68: 1 | H68: 1 | I68: 2.45 | J68: 2 | K68: 1 | L68: Home
A69: L1_0068 | B69: 46277 | C69: Notts County | D69: Bradford City | E69: 0.49 | F69: 0.5 | G69: 0 | H69: 1 | I69: 0.99 | J69: 1 | K69: 1 | L69: Home
A70: L1_0069 | B70: 46277 | C70: Oxford United | D70: Burton Albion | E70: 1.21 | F70: 0.47 | G70: 3 | H70: 0 | I70: 1.68 | J70: 3 | K70: 1 | L70: Home
A71: L1_0070 | B71: 46277 | C71: Plymouth Argyle | D71: Barnsley | E71: 0.99 | F71: 0.77 | G71: 3 | H71: 0 | I71: 1.76 | J71: 3 | K71: 1 | L71: Home
A72: L1_0071 | B72: 46277 | C72: Sheffield Wednesday | D72: Wigan Athletic | E72: 0.82 | F72: 1.59 | G72: 0 | H72: 0 | I72: 2.41 | J72: 0 | K72: 1 | L72: Home
A73: L1_0072 | B73: 46277 | C73: Stockport County | D73: Leicester City | E73: 2.29 | F73: 1.21 | G73: 3 | H73: 4 | I73: 3.5 | J73: 7 | K73: 1 | L73: Home
A74: L1_0073 | B74: 46282 | C74: AFC Wimbledon | D74: Milton Keynes Dons | K74: 1 | L74: Home
A75: L1_0074 | B75: 46284 | C75: Barnsley | D75: Leicester City | K75: 1 | L75: Home
A76: L1_0075 | B76: 46284 | C76: Blackpool | D76: Plymouth Argyle | K76: 1 | L76: Home
A77: L1_0076 | B77: 46284 | C77: Bromley | D77: Huddersfield Town | K77: 1 | L77: Home
A78: L1_0077 | B78: 46284 | C78: Burton Albion | D78: Mansfield Town | K78: 1 | L78: Home
A79: L1_0078 | B79: 46284 | C79: Leyton Orient | D79: Stevenage | K79: 1 | L79: Home
A80: L1_0079 | B80: 46284 | C80: Luton Town | D80: Bradford City | K80: 1 | L80: Home
A81: L1_0080 | B81: 46284 | C81: Oxford United | D81: Cambridge United | K81: 1 | L81: Home
A82: L1_0081 | B82: 46284 | C82: Peterborough United | D82: Doncaster Rovers | K82: 1 | L82: Home
A83: L1_0082 | B83: 46284 | C83: Reading | D83: Notts County | K83: 1 | L83: Home
A84: L1_0083 | B84: 46284 | C84: Sheffield Wednesday | D84: Stockport County | K84: 1 | L84: Home
A85: L1_0084 | B85: 46284 | C85: Wigan Athletic | D85: Wycombe Wanderers | K85: 1 | L85: Home
... A553: L1_0552 | B553: 46515 | C553: Wycombe Wanderers | D553: Barnsley | K553: 1 | L553: Home

Sheet Away Sheet
A1: Match ID | B1: Date | C1: Opponent | D1: Team | E1: Opponent xG | F1: Team xG | G1: Opponent Goals | H1: Team Goals | I1: Total xG | J1: Total Goals | K1: Match ID count | L1: Venue
A2: L1_0001 | B2: 46249 | C2: Barnsley | D2: Bromley | E2: 1.32 | F2: 1.42 | G2: 0 | H2: 1 | I2: 2.74 | J2: 1 | K2: 1 | L2: Away
A3: L1_0002 | B3: 46249 | C3: Blackpool | D3: Wycombe Wanderers | E3: 2.37 | F3: 1.29 | G3: 1 | H3: 1 | I3: 3.66 | J3: 2 | K3: 1 | L3: Away
A4: L1_0003 | B4: 46249 | C4: Bradford City | D4: Peterborough United | E4: 1.97 | F4: 1.11 | G4: 2 | H4: 0 | I4: 3.08 | J4: 2 | K4: 1 | L4: Away
A5: L1_0004 | B5: 46249 | C5: Burton Albion | D5: Stevenage | E5: 0.94 | F5: 0.53 | G5: 1 | H5: 1 | I5: 1.47 | J5: 2 | K5: 1 | L5: Away
A6: L1_0005 | B6: 46249 | C6: Cambridge United | D6: Wigan Athletic | E6: 1.74 | F6: 2.2 | G6: 3 | H6: 2 | I6: 3.94 | J6: 5 | K6: 1 | L6: Away
A7: L1_0006 | B7: 46249 | C7: Huddersfield Town | D7: AFC Wimbledon | E7: 1.24 | F7: 0.38 | G7: 3 | H7: 0 | I7: 1.62 | J7: 3 | K7: 1 | L7: Away
A8: L1_0007 | B8: 46249 | C8: Leyton Orient | D8: Sheffield Wednesday | E8: 1.38 | F8: 2.84 | G8: 1 | H8: 2 | I8: 4.22 | J8: 3 | K8: 1 | L8: Away
A9: L1_0008 | B9: 46249 | C9: Mansfield Town | D9: Doncaster Rovers | E9: 1.44 | F9: 1.06 | G9: 2 | H9: 1 | I9: 2.5 | J9: 3 | K9: 1 | L9: Away
A10: L1_0009 | B10: 46249 | C10: Notts County | D10: Leicester City | E10: 2.18 | F10: 0.74 | G10: 1 | H10: 1 | I10: 2.92 | J10: 2 | K10: 1 | L10: Away
A11: L1_0010 | B11: 46249 | C11: Oxford United | D11: Milton Keynes Dons | E11: 1.83 | F11: 2.2 | G11: 2 | H11: 2 | I11: 4.03 | J11: 4 | K11: 1 | L11: Away
A12: L1_0011 | B12: 46249 | C12: Plymouth Argyle | D12: Stockport County | E12: 0.92 | F12: 1.81 | G12: 1 | H12: 3 | I12: 2.73 | J12: 4 | K12: 1 | L12: Away
A13: L1_0012 | B13: 46249 | C13: Reading | D13: Luton Town | E13: 1.61 | F13: 1.65 | G13: 3 | H13: 4 | I13: 3.26 | J13: 7 | K13: 1 | L13: Away
... A60: L1_0059 | B60: 46272 | C60: Bromley | D60: AFC Wimbledon | E60: 0.55 | F60: 1.22 | G60: 0 | H60: 2 | I60: 1.77 | J60: 2 | K60: 1 | L60: Away
A61: L1_0060 | B61: 46273 | C61: Oxford United | D61: Reading | K61: 1 | L61: Away
A62: L1_0061 | B62: 46275 | C62: Stevenage | D62: Luton Town | E62: 1.31 | F62: 0.89 | G62: 2 | H62: 1 | I62: 2.2 | J62: 3 | K62: 1 | L62: Away
A63: L1_0062 | B63: 46277 | C63: AFC Wimbledon | D63: Doncaster Rovers | E63: 0.81 | F63: 2.41 | G63: 1 | H63: 0 | I63: 3.22 | J63: 1 | K63: 1 | L63: Away
A64: L1_0063 | B64: 46277 | C64: Blackpool | D64: Bromley | E64: 1.17 | F64: 1.38 | G64: 2 | H64: 2 | I64: 2.55 | J64: 4 | K64: 1 | L64: Away
A65: L1_0064 | B65: 46277 | C65: Cambridge United | D65: Reading | E65: 0.94 | F65: 1.99 | G65: 2 | H65: 1 | I65: 2.93 | J65: 3 | K65: 1 | L65: Away
A66: L1_0065 | B66: 46277 | C66: Leyton Orient | D66: Wycombe Wanderers | E66: 0.88 | F66: 1.16 | G66: 2 | H66: 3 | I66: 2.04 | J66: 5 | K66: 1 | L66: Away
A67: L1_0066 | B67: 46277 | C67: Mansfield Town | D67: Huddersfield Town | E67: 0.86 | F67: 1.36 | G67: 0 | H67: 0 | I67: 2.22 | J67: 0 | K67: 1 | L67: Away
A68: L1_0067 | B68: 46277 | C68: Milton Keynes Dons | D68: Peterborough United | E68: 1.24 | F68: 1.21 | G68: 1 | H68: 1 | I68: 2.45 | J68: 2 | K68: 1 | L68: Away
A69: L1_0068 | B69: 46277 | C69: Notts County | D69: Bradford City | E69: 0.49 | F69: 0.5 | G69: 0 | H69: 1 | I69: 0.99 | J69: 1 | K69: 1 | L69: Away
A70: L1_0069 | B70: 46277 | C70: Oxford United | D70: Burton Albion | E70: 1.21 | F70: 0.47 | G70: 3 | H70: 0 | I70: 1.68 | J70: 3 | K70: 1 | L70: Away
A71: L1_0070 | B71: 46277 | C71: Plymouth Argyle | D71: Barnsley | E71: 0.99 | F71: 0.77 | G71: 3 | H71: 0 | I71: 1.76 | J71: 3 | K71: 1 | L71: Away
A72: L1_0071 | B72: 46277 | C72: Sheffield Wednesday | D72: Wigan Athletic | E72: 0.82 | F72: 1.59 | G72: 0 | H72: 0 | I72: 2.41 | J72: 0 | K72: 1 | L72: Away
A73: L1_0072 | B73: 46277 | C73: Stockport County | D73: Leicester City | E73: 2.29 | F73: 1.21 | G73: 3 | H73: 4 | I73: 3.5 | J73: 7 | K73: 1 | L73: Away
A74: L1_0073 | B74: 46282 | C74: AFC Wimbledon | D74: Milton Keynes Dons | K74: 1 | L74: Away
A75: L1_0074 | B75: 46284 | C75: Barnsley | D75: Leicester City | K75: 1 | L75: Away
A76: L1_0075 | B76: 46284 | C76: Blackpool | D76: Plymouth Argyle | K76: 1 | L76: Away
A77: L1_0076 | B77: 46284 | C77: Bromley | D77: Huddersfield Town | K77: 1 | L77: Away
A78: L1_0077 | B78: 46284 | C78: Burton Albion | D78: Mansfield Town | K78: 1 | L78: Away
A79: L1_0078 | B79: 46284 | C79: Leyton Orient | D79: Stevenage | K79: 1 | L79: Away
A80: L1_0079 | B80: 46284 | C80: Luton Town | D80: Bradford City | K80: 1 | L80: Away
A81: L1_0080 | B81: 46284 | C81: Oxford United | D81: Cambridge United | K81: 1 | L81: Away
A82: L1_0081 | B82: 46284 | C82: Peterborough United | D82: Doncaster Rovers | K82: 1 | L82: Away
A83: L1_0082 | B83: 46284 | C83: Reading | D83: Notts County | K83: 1 | L83: Away
A84: L1_0083 | B84: 46284 | C84: Sheffield Wednesday | D84: Stockport County | K84: 1 | L84: Away
A85: L1_0084 | B85: 46284 | C85: Wigan Athletic | D85: Wycombe Wanderers | K85: 1 | L85: Away
... A553: L1_0552 | B553: 46515 | C553: Wycombe Wanderers | D553: Barnsley | K553: 1 | L553: Away

Sheet Team Level
A1: Match ID | B1: Date | C1: Team | D1: Opponent | E1: Team xG | F1: Opponent xG | G1: Team Goals | H1: Opponent Goals | I1: Total xG | J1: Total Goals | K1: Match ID count | L1: Venue | M1: xG Diff | N1: Goal Diff | O1: xG Overperformance | P1: Result | Q1: Recency Rank | R1: Match Key | S1: Chrono Rank | T1: Chrono Key
A2: L1_0001 | B2: 46249 | C2: Barnsley | D2: Bromley | E2: 1.32 | F2: 1.42 | G2: 0 | H2: 1 | I2: 2.74 | J2: 1 | K2: 1 | L2: Home | M2: -0.1 | N2: -1 | O2: -1.32 | P2: Loss | Q2: =IF(Team_Level[[#This Row],[Result]]="","",COUNTIFS(Team_Level[Team],Team_Level[[#This Row],[Team]],Team_Level[Date],">="&Team_Level[[#This Row],[Date]],Team_Level[Result],"<>")) -> 6 | R2: =Team_Level[[#This Row],[Team]]&"-"&Team_Level[[#This Row],[Recency Rank]] -> Barnsley-6 | S2: =IF(Team_Level[[#This Row],[Result]]="","",COUNTIFS(Team_Level[Team],Team_Level[[#This Row],[Team]],Team_Level[Date],"<="&Team_Level[[#This Row],[Date]],Team_Level[Result],"<>")) -> 1 | T2: =Team_Level[[#This Row],[Team]]&"-"&Team_Level[[#This Row],[Chrono Rank]] -> Barnsley-1
A3: L1_0002 | B3: 46249 | C3: Blackpool | D3: Wycombe Wanderers | E3: 2.37 | F3: 1.29 | G3: 1 | H3: 1 | I3: 3.66 | J3: 2 | K3: 1 | L3: Home | M3: 1.08 | N3: 0 | O3: -1.37 | P3: Draw | Q3: =IF(Team_Level[[#This Row],[Result]]="","",COUNTIFS(Team_Level[Team],Team_Level[[#This Row],[Team]],Team_Level[Date],">="&Team_Level[[#This Row],[Date]],Team_Level[Result],"<>")) -> 6 | R3: =Team_Level[[#This Row],[Team]]&"-"&Team_Level[[#This Row],[Recency Rank]] -> Blackpool-6 | S3: =IF(Team_Level[[#This Row],[Result]]="","",COUNTIFS(Team_Level[Team],Team_Level[[#This Row],[Team]],Team_Level[Date],"<="&Team_Level[[#This Row],[Date]],Team_Level[Result],"<>")) -> 1 | T3: =Team_Level[[#This Row],[Team]]&"-"&Team_Level[[#This Row],[Chrono Rank]] -> Blackpool-1
A4: L1_0003 | B4: 46249 | C4: Bradford City | D4: Peterborough United | E4: 1.97 | F4: 1.11 | G4: 2 | H4: 0 | I4: 3.08 | J4: 2 | K4: 1 | L4: Home | M4: 0.86 | N4: 2 | O4: 0.03 | P4: Win | Q4: =IF(Team_Level[[#This Row],[Result]]="","",COUNTIFS(Team_Level[Team],Team_Level[[#This Row],[Team]],Team_Level[Date],">="&Team_Level[[#This Row],[Date]],Team_Level[Result],"<>")) -> 6 | R4: =Team_Level[[#This Row],[Team]]&"-"&Team_Level[[#This Row],[Recency Rank]] -> Bradford City-6 | S4: =IF(Team_Level[[#This Row],[Result]]="","",COUNTIFS(Team_Level[Team],Team_Level[[#This Row],[Team]],Team_Level[Date],"<="&Team_Level[[#This Row],[Date]],Team_Level[Result],"<>")) -> 1 | T4: =Team_Level[[#This Row],[Team]]&"-"&Team_Level[[#This Row],[Chrono Rank]] -> Bradford City-1
A5: L1_0004 | B5: 46249 | C5: Burton Albion | D5: Stevenage | E5: 0.94 | F5: 0.53 | G5: 1 | H5: 1 | I5: 1.47 | J5: 2 | K5: 1 | L5: Home | M5: 0.41 | N5: 0 | O5: 0.06 | P5: Draw | Q5: =IF(Team_Level[[#This Row],[Result]]="","",COUNTIFS(Team_Level[Team],Team_Level[[#This Row],[Team]],Team_Level[Date],">="&Team_Level[[#This Row],[Date]],Team_Level[Result],"<>")) -> 6 | R5: =Team_Level[[#This Row],[Team]]&"-"&Team_Level[[#This Row],[Recency Rank]] -> Burton Albion-6 | S5: =IF(Team_Level[[#This Row],[Result]]="","",COUNTIFS(Team_Level[Team],Team_Level[[#This Row],[Team]],Team_Level[Date],"<="&Team_Level[[#This Row],[Date]],Team_Level[Result],"<>")) -> 1 | T5: =Team_Level[[#This Row],[Team]]&"-"&Team_Level[[#This Row],[Chrono Rank]] -> Burton Albion-1
A6: L1_0005 | B6: 46249 | C6: Cambridge United | D6: Wigan Athletic | E6: 1.74 | F6: 2.2 | G6: 3 | H6: 2 | I6: 3.94 | J6: 5 | K6: 1 | L6: Home | M6: -0.46 | N6: 1 | O6: 1.26 | P6: Win | Q6: =IF(Team_Level[[#This Row],[Result]]="","",COUNTIFS(Team_Level[Team],Team_Level[[#This Row],[Team]],Team_Level[Date],">="&Team_Level[[#This Row],[Date]],Team_Level[Result],"<>")) -> 6 | R6: =Team_Level[[#This Row],[Team]]&"-"&Team_Level[[#This Row],[Recency Rank]] -> Cambridge United-6 | S6: =IF(Team_Level[[#This Row],[Result]]="","",COUNTIFS(Team_Level[Team],Team_Level[[#This Row],[Team]],Team_Level[Date],"<="&Team_Level[[#This Row],[Date]],Team_Level[Result],"<>")) -> 1 | T6: =Team_Level[[#This Row],[Team]]&"-"&Team_Level[[#This Row],[Chrono Rank]] -> Cambridge United-1
A7: L1_0006 | B7: 46249 | C7: Huddersfield Town | D7: AFC Wimbledon | E7: 1.24 | F7: 0.38 | G7: 3 | H7: 0 | I7: 1.62 | J7: 3 | K7: 1 | L7: Home | M7: 0.86 | N7: 3 | O7: 1.76 | P7: Win | Q7: =IF(Team_Level[[#This Row],[Result]]="","",COUNTIFS(Team_Level[Team],Team_Level[[#This Row],[Team]],Team_Level[Date],">="&Team_Level[[#This Row],[Date]],Team_Level[Result],"<>")) -> 6 | R7: =Team_Level[[#This Row],[Team]]&"-"&Team_Level[[#This Row],[Recency Rank]] -> Huddersfield Town-6 | S7: =IF(Team_Level[[#This Row],[Result]]="","",COUNTIFS(Team_Level[Team],Team_Level[[#This Row],[Team]],Team_Level[Date],"<="&Team_Level[[#This Row],[Date]],Team_Level[Result],"<>")) -> 1 | T7: =Team_Level[[#This Row],[Team]]&"-"&Team_Level[[#This Row],[Chrono Rank]] -> Huddersfield Town-1
A8: L1_0007 | B8: 46249 | C8: Leyton Orient | D8: Sheffield Wednesday | E8: 1.38 | F8: 2.84 | G8: 1 | H8: 2 | I8: 4.22 | J8: 3 | K8: 1 | L8: Home | M8: -1.46 | N8: -1 | O8: -0.38 | P8: Loss | Q8: =IF(Team_Level[[#This Row],[Result]]="","",COUNTIFS(Team_Level[Team],Team_Level[[#This Row],[Team]],Team_Level[Date],">="&Team_Level[[#This Row],[Date]],Team_Level[Result],"<>")) -> 6 | R8: =Team_Level[[#This Row],[Team]]&"-"&Team_Level[[#This Row],[Recency Rank]] -> Leyton Orient-6 | S8: =IF(Team_Level[[#This Row],[Result]]="","",COUNTIFS(Team_Level[Team],Team_Level[[#This Row],[Team]],Team_Level[Date],"<="&Team_Level[[#This Row],[Date]],Team_Level[Result],"<>")) -> 1 | T8: =Team_Level[[#This Row],[Team]]&"-"&Team_Level[[#This Row],[Chrono Rank]] -> Leyton Orient-1
A9: L1_0008 | B9: 46249 | C9: Mansfield Town | D9: Doncaster Rovers | E9: 1.44 | F9: 1.06 | G9: 2 | H9: 1 | I9: 2.5 | J9: 3 | K9: 1 | L9: Home | M9: 0.38 | N9: 1 | O9: 0.56 | P9: Win | Q9: =IF(Team_Level[[#This Row],[Result]]="","",COUNTIFS(Team_Level[Team],Team_Level[[#This Row],[Team]],Team_Level[Date],">="&Team_Level[[#This Row],[Date]],Team_Level[Result],"<>")) -> 6 | R9: =Team_Level[[#This Row],[Team]]&"-"&Team_Level[[#This Row],[Recency Rank]] -> Mansfield Town-6 | S9: =IF(Team_Level[[#This Row],[Result]]="","",COUNTIFS(Team_Level[Team],Team_Level[[#This Row],[Team]],Team_Level[Date],"<="&Team_Level[[#This Row],[Date]],Team_Level[Result],"<>")) -> 1 | T9: =Team_Level[[#This Row],[Team]]&"-"&Team_Level[[#This Row],[Chrono Rank]] -> Mansfield Town-1
A10: L1_0009 | B10: 46249 | C10: Notts County | D10: Leicester City | E10: 2.18 | F10: 0.74 | G10: 1 | H10: 1 | I10: 2.92 | J10: 2 | K10: 1 | L10: Home | M10: 1.44 | N10: 0 | O10: -1.18 | P10: Draw | Q10: =IF(Team_Level[[#This Row],[Result]]="","",COUNTIFS(Team_Level[Team],Team_Level[[#This Row],[Team]],Team_Level[Date],">="&Team_Level[[#This Row],[Date]],Team_Level[Result],"<>")) -> 6 | R10: =Team_Level[[#This Row],[Team]]&"-"&Team_Level[[#This Row],[Recency Rank]] -> Notts County-6 | S10: =IF(Team_Level[[#This Row],[Result]]="","",COUNTIFS(Team_Level[Team],Team_Level[[#This Row],[Team]],Team_Level[Date],"<="&Team_Level[[#This Row],[Date]],Team_Level[Result],"<>")) -> 1 | T10: =Team_Level[[#This Row],[Team]]&"-"&Team_Level[[#This Row],[Chrono Rank]] -> Notts County-1
A11: L1_0010 | B11: 46249 | C11: Oxford United | D11: Milton Keynes Dons | E11: 1.83 | F11: 2.2 | G11: 2 | H11: 2 | I11: 4.03 | J11: 4 | K11: 1 | L11: Home | M11: -0.37 | N11: 0 | O11: 0.17 | P11: Draw | Q11: =IF(Team_Level[[#This Row],[Result]]="","",COUNTIFS(Team_Level[Team],Team_Level[[#This Row],[Team]],Team_Level[Date],">="&Team_Level[[#This Row],[Date]],Team_Level[Result],"<>")) -> 5 | R11: =Team_Level[[#This Row],[Team]]&"-"&Team_Level[[#This Row],[Recency Rank]] -> Oxford United-5 | S11: =IF(Team_Level[[#This Row],[Result]]="","",COUNTIFS(Team_Level[Team],Team_Level[[#This Row],[Team]],Team_Level[Date],"<="&Team_Level[[#This Row],[Date]],Team_Level[Result],"<>")) -> 1 | T11: =Team_Level[[#This Row],[Team]]&"-"&Team_Level[[#This Row],[Chrono Rank]] -> Oxford United-1
A12: L1_0011 | B12: 46249 | C12: Plymouth Argyle | D12: Stockport County | E12: 0.92 | F12: 1.81 | G12: 1 | H12: 3 | I12: 2.73 | J12: 4 | K12: 1 | L12: Home | M12: -0.89 | N12: -2 | O12: 0.08 | P12: Loss | Q12: =IF(Team_Level[[#This Row],[Result]]="","",COUNTIFS(Team_Level[Team],Team_Level[[#This Row],[Team]],Team_Level[Date],">="&Team_Level[[#This Row],[Date]],Team_Level[Result],"<>")) -> 6 | R12: =Team_Level[[#This Row],[Team]]&"-"&Team_Level[[#This Row],[Recency Rank]] -> Plymouth Argyle-6 | S12: =IF(Team_Level[[#This Row],[Result]]="","",COUNTIFS(Team_Level[Team],Team_Level[[#This Row],[Team]],Team_Level[Date],"<="&Team_Level[[#This Row],[Date]],Team_Level[Result],"<>")) -> 1 | T12: =Team_Level[[#This Row],[Team]]&"-"&Team_Level[[#This Row],[Chrono Rank]] -> Plymouth Argyle-1
A13: L1_0012 | B13: 46249 | C13: Reading | D13: Luton Town | E13: 1.61 | F13: 1.65 | G13: 3 | H13: 4 | I13: 3.26 | J13: 7 | K13: 1 | L13: Home | M13: -0.04 | N13: -1 | O13: 1.39 | P13: Loss | Q13: =IF(Team_Level[[#This Row],[Result]]="","",COUNTIFS(Team_Level[Team],Team_Level[[#This Row],[Team]],Team_Level[Date],">="&Team_Level[[#This Row],[Date]],Team_Level[Result],"<>")) -> 5 | R13: =Team_Level[[#This Row],[Team]]&"-"&Team_Level[[#This Row],[Recency Rank]] -> Reading-5 | S13: =IF(Team_Level[[#This Row],[Result]]="","",COUNTIFS(Team_Level[Team],Team_Level[[#This Row],[Team]],Team_Level[Date],"<="&Team_Level[[#This Row],[Date]],Team_Level[Result],"<>")) -> 1 | T13: =Team_Level[[#This Row],[Team]]&"-"&Team_Level[[#This Row],[Chrono Rank]] -> Reading-1
... A60: L1_0059 | B60: 46272 | C60: Bromley | D60: AFC Wimbledon | E60: 0.55 | F60: 1.22 | G60: 0 | H60: 2 | I60: 1.77 | J60: 2 | K60: 1 | L60: Home | M60: -0.67 | N60: -2 | O60: -0.55 | P60: Loss | Q60: =IF(Team_Level[[#This Row],[Result]]="","",COUNTIFS(Team_Level[Team],Team_Level[[#This Row],[Team]],Team_Level[Date],">="&Team_Level[[#This Row],[Date]],Team_Level[Result],"<>")) -> 2 | R60: =Team_Level[[#This Row],[Team]]&"-"&Team_Level[[#This Row],[Recency Rank]] -> Bromley-2 | S60: =IF(Team_Level[[#This Row],[Result]]="","",COUNTIFS(Team_Level[Team],Team_Level[[#This Row],[Team]],Team_Level[Date],"<="&Team_Level[[#This Row],[Date]],Team_Level[Result],"<>")) -> 5 | T60: =Team_Level[[#This Row],[Team]]&"-"&Team_Level[[#This Row],[Chrono Rank]] -> Bromley-5
A61: L1_0060 | B61: 46273 | C61: Oxford United | D61: Reading | K61: 1 | L61: Home | Q61: =IF(Team_Level[[#This Row],[Result]]="","",COUNTIFS(Team_Level[Team],Team_Level[[#This Row],[Team]],Team_Level[Date],">="&Team_Level[[#This Row],[Date]],Team_Level[Result],"<>")) | R61: =Team_Level[[#This Row],[Team]]&"-"&Team_Level[[#This Row],[Recency Rank]] -> Oxford United- | S61: =IF(Team_Level[[#This Row],[Result]]="","",COUNTIFS(Team_Level[Team],Team_Level[[#This Row],[Team]],Team_Level[Date],"<="&Team_Level[[#This Row],[Date]],Team_Level[Result],"<>")) | T61: =Team_Level[[#This Row],[Team]]&"-"&Team_Level[[#This Row],[Chrono Rank]] -> Oxford United-
A62: L1_0061 | B62: 46275 | C62: Stevenage | D62: Luton Town | E62: 1.31 | F62: 0.89 | G62: 2 | H62: 1 | I62: 2.2 | J62: 3 | K62: 1 | L62: Home | M62: 0.42 | N62: 1 | O62: 0.69 | P62: Win | Q62: =IF(Team_Level[[#This Row],[Result]]="","",COUNTIFS(Team_Level[Team],Team_Level[[#This Row],[Team]],Team_Level[Date],">="&Team_Level[[#This Row],[Date]],Team_Level[Result],"<>")) -> 1 | R62: =Team_Level[[#This Row],[Team]]&"-"&Team_Level[[#This Row],[Recency Rank]] -> Stevenage-1 | S62: =IF(Team_Level[[#This Row],[Result]]="","",COUNTIFS(Team_Level[Team],Team_Level[[#This Row],[Team]],Team_Level[Date],"<="&Team_Level[[#This Row],[Date]],Team_Level[Result],"<>")) -> 6 | T62: =Team_Level[[#This Row],[Team]]&"-"&Team_Level[[#This Row],[Chrono Rank]] -> Stevenage-6
A63: L1_0062 | B63: 46277 | C63: AFC Wimbledon | D63: Doncaster Rovers | E63: 0.81 | F63: 2.41 | G63: 1 | H63: 0 | I63: 3.22 | J63: 1 | K63: 1 | L63: Home | M63: -1.6 | N63: 1 | O63: 0.19 | P63: Win | Q63: =IF(Team_Level[[#This Row],[Result]]="","",COUNTIFS(Team_Level[Team],Team_Level[[#This Row],[Team]],Team_Level[Date],">="&Team_Level[[#This Row],[Date]],Team_Level[Result],"<>")) -> 1 | R63: =Team_Level[[#This Row],[Team]]&"-"&Team_Level[[#This Row],[Recency Rank]] -> AFC Wimbledon-1 | S63: =IF(Team_Level[[#This Row],[Result]]="","",COUNTIFS(Team_Level[Team],Team_Level[[#This Row],[Team]],Team_Level[Date],"<="&Team_Level[[#This Row],[Date]],Team_Level[Result],"<>")) -> 6 | T63: =Team_Level[[#This Row],[Team]]&"-"&Team_Level[[#This Row],[Chrono Rank]] -> AFC Wimbledon-6
A64: L1_0063 | B64: 46277 | C64: Blackpool | D64: Bromley | E64: 1.17 | F64: 1.38 | G64: 2 | H64: 2 | I64: 2.55 | J64: 4 | K64: 1 | L64: Home | M64: -0.21 | N64: 0 | O64: 0.83 | P64: Draw | Q64: =IF(Team_Level[[#This Row],[Result]]="","",COUNTIFS(Team_Level[Team],Team_Level[[#This Row],[Team]],Team_Level[Date],">="&Team_Level[[#This Row],[Date]],Team_Level[Result],"<>")) -> 1 | R64: =Team_Level[[#This Row],[Team]]&"-"&Team_Level[[#This Row],[Recency Rank]] -> Blackpool-1 | S64: =IF(Team_Level[[#This Row],[Result]]="","",COUNTIFS(Team_Level[Team],Team_Level[[#This Row],[Team]],Team_Level[Date],"<="&Team_Level[[#This Row],[Date]],Team_Level[Result],"<>")) -> 6 | T64: =Team_Level[[#This Row],[Team]]&"-"&Team_Level[[#This Row],[Chrono Rank]] -> Blackpool-6
A65: L1_0064 | B65: 46277 | C65: Cambridge United | D65: Reading | E65: 0.94 | F65: 1.99 | G65: 2 | H65: 1 | I65: 2.93 | J65: 3 | K65: 1 | L65: Home | M65: -1.05 | N65: 1 | O65: 1.06 | P65: Win | Q65: =IF(Team_Level[[#This Row],[Result]]="","",COUNTIFS(Team_Level[Team],Team_Level[[#This Row],[Team]],Team_Level[Date],">="&Team_Level[[#This Row],[Date]],Team_Level[Result],"<>")) -> 1 | R65: =Team_Level[[#This Row],[Team]]&"-"&Team_Level[[#This Row],[Recency Rank]] -> Cambridge United-1 | S65: =IF(Team_Level[[#This Row],[Result]]="","",COUNTIFS(Team_Level[Team],Team_Level[[#This Row],[Team]],Team_Level[Date],"<="&Team_Level[[#This Row],[Date]],Team_Level[Result],"<>")) -> 6 | T65: =Team_Level[[#This Row],[Team]]&"-"&Team_Level[[#This Row],[Chrono Rank]] -> Cambridge United-6
A66: L1_0065 | B66: 46277 | C66: Leyton Orient | D66: Wycombe Wanderers | E66: 0.88 | F66: 1.16 | G66: 2 | H66: 3 | I66: 2.04 | J66: 5 | K66: 1 | L66: Home | M66: -0.28 | N66: -1 | O66: 1.12 | P66: Loss | Q66: =IF(Team_Level[[#This Row],[Result]]="","",COUNTIFS(Team_Level[Team],Team_Level[[#This Row],[Team]],Team_Level[Date],">="&Team_Level[[#This Row],[Date]],Team_Level[Result],"<>")) -> 1 | R66: =Team_Level[[#This Row],[Team]]&"-"&Team_Level[[#This Row],[Recency Rank]] -> Leyton Orient-1 | S66: =IF(Team_Level[[#This Row],[Result]]="","",COUNTIFS(Team_Level[Team],Team_Level[[#This Row],[Team]],Team_Level[Date],"<="&Team_Level[[#This Row],[Date]],Team_Level[Result],"<>")) -> 6 | T66: =Team_Level[[#This Row],[Team]]&"-"&Team_Level[[#This Row],[Chrono Rank]] -> Leyton Orient-6
A67: L1_0066 | B67: 46277 | C67: Mansfield Town | D67: Huddersfield Town | E67: 0.86 | F67: 1.36 | G67: 0 | H67: 0 | I67: 2.22 | J67: 0 | K67: 1 | L67: Home | M67: -0.5 | N67: 0 | O67: -0.86 | P67: Draw | Q67: =IF(Team_Level[[#This Row],[Result]]="","",COUNTIFS(Team_Level[Team],Team_Level[[#This Row],[Team]],Team_Level[Date],">="&Team_Level[[#This Row],[Date]],Team_Level[Result],"<>")) -> 1 | R67: =Team_Level[[#This Row],[Team]]&"-"&Team_Level[[#This Row],[Recency Rank]] -> Mansfield Town-1 | S67: =IF(Team_Level[[#This Row],[Result]]="","",COUNTIFS(Team_Level[Team],Team_Level[[#This Row],[Team]],Team_Level[Date],"<="&Team_Level[[#This Row],[Date]],Team_Level[Result],"<>")) -> 6 | T67: =Team_Level[[#This Row],[Team]]&"-"&Team_Level[[#This Row],[Chrono Rank]] -> Mansfield Town-6
A68: L1_0067 | B68: 46277 | C68: Milton Keynes Dons | D68: Peterborough United | E68: 1.24 | F68: 1.21 | G68: 1 | H68: 1 | I68: 2.45 | J68: 2 | K68: 1 | L68: Home | M68: 0.03 | N68: 0 | O68: -0.24 | P68: Draw | Q68: =IF(Team_Level[[#This Row],[Result]]="","",COUNTIFS(Team_Level[Team],Team_Level[[#This Row],[Team]],Team_Level[Date],">="&Team_Level[[#This Row],[Date]],Team_Level[Result],"<>")) -> 1 | R68: =Team_Level[[#This Row],[Team]]&"-"&Team_Level[[#This Row],[Recency Rank]] -> Milton Keynes Dons-1 | S68: =IF(Team_Level[[#This Row],[Result]]="","",COUNTIFS(Team_Level[Team],Team_Level[[#This Row],[Team]],Team_Level[Date],"<="&Team_Level[[#This Row],[Date]],Team_Level[Result],"<>")) -> 6 | T68: =Team_Level[[#This Row],[Team]]&"-"&Team_Level[[#This Row],[Chrono Rank]] -> Milton Keynes Dons-6
A69: L1_0068 | B69: 46277 | C69: Notts County | D69: Bradford City | E69: 0.49 | F69: 0.5 | G69: 0 | H69: 1 | I69: 0.99 | J69: 1 | K69: 1 | L69: Home | M69: -0.01 | N69: -1 | O69: -0.49 | P69: Loss | Q69: =IF(Team_Level[[#This Row],[Result]]="","",COUNTIFS(Team_Level[Team],Team_Level[[#This Row],[Team]],Team_Level[Date],">="&Team_Level[[#This Row],[Date]],Team_Level[Result],"<>")) -> 1 | R69: =Team_Level[[#This Row],[Team]]&"-"&Team_Level[[#This Row],[Recency Rank]] -> Notts County-1 | S69: =IF(Team_Level[[#This Row],[Result]]="","",COUNTIFS(Team_Level[Team],Team_Level[[#This Row],[Team]],Team_Level[Date],"<="&Team_Level[[#This Row],[Date]],Team_Level[Result],"<>")) -> 6 | T69: =Team_Level[[#This Row],[Team]]&"-"&Team_Level[[#This Row],[Chrono Rank]] -> Notts County-6
A70: L1_0069 | B70: 46277 | C70: Oxford United | D70: Burton Albion | E70: 1.21 | F70: 0.47 | G70: 3 | H70: 0 | I70: 1.68 | J70: 3 | K70: 1 | L70: Home | M70: 0.74 | N70: 3 | O70: 1.79 | P70: Win | Q70: =IF(Team_Level[[#This Row],[Result]]="","",COUNTIFS(Team_Level[Team],Team_Level[[#This Row],[Team]],Team_Level[Date],">="&Team_Level[[#This Row],[Date]],Team_Level[Result],"<>")) -> 1 | R70: =Team_Level[[#This Row],[Team]]&"-"&Team_Level[[#This Row],[Recency Rank]] -> Oxford United-1 | S70: =IF(Team_Level[[#This Row],[Result]]="","",COUNTIFS(Team_Level[Team],Team_Level[[#This Row],[Team]],Team_Level[Date],"<="&Team_Level[[#This Row],[Date]],Team_Level[Result],"<>")) -> 5 | T70: =Team_Level[[#This Row],[Team]]&"-"&Team_Level[[#This Row],[Chrono Rank]] -> Oxford United-5
A71: L1_0070 | B71: 46277 | C71: Plymouth Argyle | D71: Barnsley | E71: 0.99 | F71: 0.77 | G71: 3 | H71: 0 | I71: 1.76 | J71: 3 | K71: 1 | L71: Home | M71: 0.22 | N71: 3 | O71: 2.01 | P71: Win | Q71: =IF(Team_Level[[#This Row],[Result]]="","",COUNTIFS(Team_Level[Team],Team_Level[[#This Row],[Team]],Team_Level[Date],">="&Team_Level[[#This Row],[Date]],Team_Level[Result],"<>")) -> 1 | R71: =Team_Level[[#This Row],[Team]]&"-"&Team_Level[[#This Row],[Recency Rank]] -> Plymouth Argyle-1 | S71: =IF(Team_Level[[#This Row],[Result]]="","",COUNTIFS(Team_Level[Team],Team_Level[[#This Row],[Team]],Team_Level[Date],"<="&Team_Level[[#This Row],[Date]],Team_Level[Result],"<>")) -> 6 | T71: =Team_Level[[#This Row],[Team]]&"-"&Team_Level[[#This Row],[Chrono Rank]] -> Plymouth Argyle-6
A72: L1_0071 | B72: 46277 | C72: Sheffield Wednesday | D72: Wigan Athletic | E72: 0.82 | F72: 1.59 | G72: 0 | H72: 0 | I72: 2.41 | J72: 0 | K72: 1 | L72: Home | M72: -0.77 | N72: 0 | O72: -0.82 | P72: Draw | Q72: =IF(Team_Level[[#This Row],[Result]]="","",COUNTIFS(Team_Level[Team],Team_Level[[#This Row],[Team]],Team_Level[Date],">="&Team_Level[[#This Row],[Date]],Team_Level[Result],"<>")) -> 1 | R72: =Team_Level[[#This Row],[Team]]&"-"&Team_Level[[#This Row],[Recency Rank]] -> Sheffield Wednesday-1 | S72: =IF(Team_Level[[#This Row],[Result]]="","",COUNTIFS(Team_Level[Team],Team_Level[[#This Row],[Team]],Team_Level[Date],"<="&Team_Level[[#This Row],[Date]],Team_Level[Result],"<>")) -> 6 | T72: =Team_Level[[#This Row],[Team]]&"-"&Team_Level[[#This Row],[Chrono Rank]] -> Sheffield Wednesday-6
A73: L1_0072 | B73: 46277 | C73: Stockport County | D73: Leicester City | E73: 2.29 | F73: 1.21 | G73: 3 | H73: 4 | I73: 3.5 | J73: 7 | K73: 1 | L73: Home | M73: 1.08 | N73: -1 | O73: 0.71 | P73: Loss | Q73: =IF(Team_Level[[#This Row],[Result]]="","",COUNTIFS(Team_Level[Team],Team_Level[[#This Row],[Team]],Team_Level[Date],">="&Team_Level[[#This Row],[Date]],Team_Level[Result],"<>")) -> 1 | R73: =Team_Level[[#This Row],[Team]]&"-"&Team_Level[[#This Row],[Recency Rank]] -> Stockport County-1 | S73: =IF(Team_Level[[#This Row],[Result]]="","",COUNTIFS(Team_Level[Team],Team_Level[[#This Row],[Team]],Team_Level[Date],"<="&Team_Level[[#This Row],[Date]],Team_Level[Result],"<>")) -> 6 | T73: =Team_Level[[#This Row],[Team]]&"-"&Team_Level[[#This Row],[Chrono Rank]] -> Stockport County-6
A74: L1_0073 | B74: 46282 | C74: AFC Wimbledon | D74: Milton Keynes Dons | K74: 1 | L74: Home | Q74: =IF(Team_Level[[#This Row],[Result]]="","",COUNTIFS(Team_Level[Team],Team_Level[[#This Row],[Team]],Team_Level[Date],">="&Team_Level[[#This Row],[Date]],Team_Level[Result],"<>")) | R74: =Team_Level[[#This Row],[Team]]&"-"&Team_Level[[#This Row],[Recency Rank]] -> AFC Wimbledon- | S74: =IF(Team_Level[[#This Row],[Result]]="","",COUNTIFS(Team_Level[Team],Team_Level[[#This Row],[Team]],Team_Level[Date],"<="&Team_Level[[#This Row],[Date]],Team_Level[Result],"<>")) | T74: =Team_Level[[#This Row],[Team]]&"-"&Team_Level[[#This Row],[Chrono Rank]] -> AFC Wimbledon-
A75: L1_0074 | B75: 46284 | C75: Barnsley | D75: Leicester City | K75: 1 | L75: Home | Q75: =IF(Team_Level[[#This Row],[Result]]="","",COUNTIFS(Team_Level[Team],Team_Level[[#This Row],[Team]],Team_Level[Date],">="&Team_Level[[#This Row],[Date]],Team_Level[Result],"<>")) | R75: =Team_Level[[#This Row],[Team]]&"-"&Team_Level[[#This Row],[Recency Rank]] -> Barnsley- | S75: =IF(Team_Level[[#This Row],[Result]]="","",COUNTIFS(Team_Level[Team],Team_Level[[#This Row],[Team]],Team_Level[Date],"<="&Team_Level[[#This Row],[Date]],Team_Level[Result],"<>")) | T75: =Team_Level[[#This Row],[Team]]&"-"&Team_Level[[#This Row],[Chrono Rank]] -> Barnsley-
A76: L1_0075 | B76: 46284 | C76: Blackpool | D76: Plymouth Argyle | K76: 1 | L76: Home | Q76: =IF(Team_Level[[#This Row],[Result]]="","",COUNTIFS(Team_Level[Team],Team_Level[[#This Row],[Team]],Team_Level[Date],">="&Team_Level[[#This Row],[Date]],Team_Level[Result],"<>")) | R76: =Team_Level[[#This Row],[Team]]&"-"&Team_Level[[#This Row],[Recency Rank]] -> Blackpool- | S76: =IF(Team_Level[[#This Row],[Result]]="","",COUNTIFS(Team_Level[Team],Team_Level[[#This Row],[Team]],Team_Level[Date],"<="&Team_Level[[#This Row],[Date]],Team_Level[Result],"<>")) | T76: =Team_Level[[#This Row],[Team]]&"-"&Team_Level[[#This Row],[Chrono Rank]] -> Blackpool-
A77: L1_0076 | B77: 46284 | C77: Bromley | D77: Huddersfield Town | K77: 1 | L77: Home | Q77: =IF(Team_Level[[#This Row],[Result]]="","",COUNTIFS(Team_Level[Team],Team_Level[[#This Row],[Team]],Team_Level[Date],">="&Team_Level[[#This Row],[Date]],Team_Level[Result],"<>")) | R77: =Team_Level[[#This Row],[Team]]&"-"&Team_Level[[#This Row],[Recency Rank]] -> Bromley- | S77: =IF(Team_Level[[#This Row],[Result]]="","",COUNTIFS(Team_Level[Team],Team_Level[[#This Row],[Team]],Team_Level[Date],"<="&Team_Level[[#This Row],[Date]],Team_Level[Result],"<>")) | T77: =Team_Level[[#This Row],[Team]]&"-"&Team_Level[[#This Row],[Chrono Rank]] -> Bromley-
A78: L1_0077 | B78: 46284 | C78: Burton Albion | D78: Mansfield Town | K78: 1 | L78: Home | Q78: =IF(Team_Level[[#This Row],[Result]]="","",COUNTIFS(Team_Level[Team],Team_Level[[#This Row],[Team]],Team_Level[Date],">="&Team_Level[[#This Row],[Date]],Team_Level[Result],"<>")) | R78: =Team_Level[[#This Row],[Team]]&"-"&Team_Level[[#This Row],[Recency Rank]] -> Burton Albion- | S78: =IF(Team_Level[[#This Row],[Result]]="","",COUNTIFS(Team_Level[Team],Team_Level[[#This Row],[Team]],Team_Level[Date],"<="&Team_Level[[#This Row],[Date]],Team_Level[Result],"<>")) | T78: =Team_Level[[#This Row],[Team]]&"-"&Team_Level[[#This Row],[Chrono Rank]] -> Burton Albion-
A79: L1_0078 | B79: 46284 | C79: Leyton Orient | D79: Stevenage | K79: 1 | L79: Home | Q79: =IF(Team_Level[[#This Row],[Result]]="","",COUNTIFS(Team_Level[Team],Team_Level[[#This Row],[Team]],Team_Level[Date],">="&Team_Level[[#This Row],[Date]],Team_Level[Result],"<>")) | R79: =Team_Level[[#This Row],[Team]]&"-"&Team_Level[[#This Row],[Recency Rank]] -> Leyton Orient- | S79: =IF(Team_Level[[#This Row],[Result]]="","",COUNTIFS(Team_Level[Team],Team_Level[[#This Row],[Team]],Team_Level[Date],"<="&Team_Level[[#This Row],[Date]],Team_Level[Result],"<>")) | T79: =Team_Level[[#This Row],[Team]]&"-"&Team_Level[[#This Row],[Chrono Rank]] -> Leyton Orient-
A80: L1_0079 | B80: 46284 | C80: Luton Town | D80: Bradford City | K80: 1 | L80: Home | Q80: =IF(Team_Level[[#This Row],[Result]]="","",COUNTIFS(Team_Level[Team],Team_Level[[#This Row],[Team]],Team_Level[Date],">="&Team_Level[[#This Row],[Date]],Team_Level[Result],"<>")) | R80: =Team_Level[[#This Row],[Team]]&"-"&Team_Level[[#This Row],[Recency Rank]] -> Luton Town- | S80: =IF(Team_Level[[#This Row],[Result]]="","",COUNTIFS(Team_Level[Team],Team_Level[[#This Row],[Team]],Team_Level[Date],"<="&Team_Level[[#This Row],[Date]],Team_Level[Result],"<>")) | T80: =Team_Level[[#This Row],[Team]]&"-"&Team_Level[[#This Row],[Chrono Rank]] -> Luton Town-
A81: L1_0080 | B81: 46284 | C81: Oxford United | D81: Cambridge United | K81: 1 | L81: Home | Q81: =IF(Team_Level[[#This Row],[Result]]="","",COUNTIFS(Team_Level[Team],Team_Level[[#This Row],[Team]],Team_Level[Date],">="&Team_Level[[#This Row],[Date]],Team_Level[Result],"<>")) | R81: =Team_Level[[#This Row],[Team]]&"-"&Team_Level[[#This Row],[Recency Rank]] -> Oxford United- | S81: =IF(Team_Level[[#This Row],[Result]]="","",COUNTIFS(Team_Level[Team],Team_Level[[#This Row],[Team]],Team_Level[Date],"<="&Team_Level[[#This Row],[Date]],Team_Level[Result],"<>")) | T81: =Team_Level[[#This Row],[Team]]&"-"&Team_Level[[#This Row],[Chrono Rank]] -> Oxford United-
A82: L1_0081 | B82: 46284 | C82: Peterborough United | D82: Doncaster Rovers | K82: 1 | L82: Home | Q82: =IF(Team_Level[[#This Row],[Result]]="","",COUNTIFS(Team_Level[Team],Team_Level[[#This Row],[Team]],Team_Level[Date],">="&Team_Level[[#This Row],[Date]],Team_Level[Result],"<>")) | R82: =Team_Level[[#This Row],[Team]]&"-"&Team_Level[[#This Row],[Recency Rank]] -> Peterborough United- | S82: =IF(Team_Level[[#This Row],[Result]]="","",COUNTIFS(Team_Level[Team],Team_Level[[#This Row],[Team]],Team_Level[Date],"<="&Team_Level[[#This Row],[Date]],Team_Level[Result],"<>")) | T82: =Team_Level[[#This Row],[Team]]&"-"&Team_Level[[#This Row],[Chrono Rank]] -> Peterborough United-
A83: L1_0082 | B83: 46284 | C83: Reading | D83: Notts County | K83: 1 | L83: Home | Q83: =IF(Team_Level[[#This Row],[Result]]="","",COUNTIFS(Team_Level[Team],Team_Level[[#This Row],[Team]],Team_Level[Date],">="&Team_Level[[#This Row],[Date]],Team_Level[Result],"<>")) | R83: =Team_Level[[#This Row],[Team]]&"-"&Team_Level[[#This Row],[Recency Rank]] -> Reading- | S83: =IF(Team_Level[[#This Row],[Result]]="","",COUNTIFS(Team_Level[Team],Team_Level[[#This Row],[Team]],Team_Level[Date],"<="&Team_Level[[#This Row],[Date]],Team_Level[Result],"<>")) | T83: =Team_Level[[#This Row],[Team]]&"-"&Team_Level[[#This Row],[Chrono Rank]] -> Reading-
A84: L1_0083 | B84: 46284 | C84: Sheffield Wednesday | D84: Stockport County | K84: 1 | L84: Home | Q84: =IF(Team_Level[[#This Row],[Result]]="","",COUNTIFS(Team_Level[Team],Team_Level[[#This Row],[Team]],Team_Level[Date],">="&Team_Level[[#This Row],[Date]],Team_Level[Result],"<>")) | R84: =Team_Level[[#This Row],[Team]]&"-"&Team_Level[[#This Row],[Recency Rank]] -> Sheffield Wednesday- | S84: =IF(Team_Level[[#This Row],[Result]]="","",COUNTIFS(Team_Level[Team],Team_Level[[#This Row],[Team]],Team_Level[Date],"<="&Team_Level[[#This Row],[Date]],Team_Level[Result],"<>")) | T84: =Team_Level[[#This Row],[Team]]&"-"&Team_Level[[#This Row],[Chrono Rank]] -> Sheffield Wednesday-
A85: L1_0084 | B85: 46284 | C85: Wigan Athletic | D85: Wycombe Wanderers | K85: 1 | L85: Home | Q85: =IF(Team_Level[[#This Row],[Result]]="","",COUNTIFS(Team_Level[Team],Team_Level[[#This Row],[Team]],Team_Level[Date],">="&Team_Level[[#This Row],[Date]],Team_Level[Result],"<>")) | R85: =Team_Level[[#This Row],[Team]]&"-"&Team_Level[[#This Row],[Recency Rank]] -> Wigan Athletic- | S85: =IF(Team_Level[[#This Row],[Result]]="","",COUNTIFS(Team_Level[Team],Team_Level[[#This Row],[Team]],Team_Level[Date],"<="&Team_Level[[#This Row],[Date]],Team_Level[Result],"<>")) | T85: =Team_Level[[#This Row],[Team]]&"-"&Team_Level[[#This Row],[Chrono Rank]] -> Wigan Athletic-
... A553: L1_0552 | B553: 46515 | C553: Wycombe Wanderers | D553: Barnsley | K553: 1 | L553: Home | Q553: =IF(Team_Level[[#This Row],[Result]]="","",COUNTIFS(Team_Level[Team],Team_Level[[#This Row],[Team]],Team_Level[Date],">="&Team_Level[[#This Row],[Date]],Team_Level[Result],"<>")) | R553: =Team_Level[[#This Row],[Team]]&"-"&Team_Level[[#This Row],[Recency Rank]] -> Wycombe Wanderers- | S553: =IF(Team_Level[[#This Row],[Result]]="","",COUNTIFS(Team_Level[Team],Team_Level[[#This Row],[Team]],Team_Level[Date],"<="&Team_Level[[#This Row],[Date]],Team_Level[Result],"<>")) | T553: =Team_Level[[#This Row],[Team]]&"-"&Team_Level[[#This Row],[Chrono Rank]] -> Wycombe Wanderers-
...

Sheet Team_Hub
A1: Row Labels | B1: Goals For | C1: xG For | D1: Goals Against | E1: xG Against | F1: Total xG Diff | G1: Total Goal Diff | H1: Total xG performance | I1: Games Played | M1: Row Labels | N1: xG For | O1: xG Against | P1: Total xG Diff
A2: AFC Wimbledon | B2: 5 | C2: 4.93 | D2: 7 | E2: 9.4 | F2: -4.47 | G2: -2 | H2: 0.07 | I2: 6 | M2: AFC Wimbledon | N2: 4.93 | O2: 9.4 | P2: -4.47
A3: Barnsley | B3: 6 | C3: 8.33 | D3: 11 | E3: 9.29 | F3: -0.96 | G3: -5 | H3: -2.33 | I3: 6 | M3: Barnsley | N3: 8.33 | O3: 9.29 | P3: -0.96
A4: Blackpool | B4: 11 | C4: 10.97 | D4: 9 | E4: 13.4 | F4: -2.43 | G4: 2 | H4: 0.03 | I4: 6 | M4: Blackpool | N4: 10.97 | O4: 13.4 | P4: -2.43
A5: Bradford City | B5: 6 | C5: 7.17 | D5: 4 | E5: 5.17 | F5: 2 | G5: 2 | H5: -1.17 | I5: 6 | M5: Bradford City | N5: 7.17 | O5: 5.17 | P5: 2
A6: Bromley | B6: 6 | C6: 6.06 | D6: 17 | E6: 10.76 | F6: -4.7 | G6: -11 | H6: -0.06 | I6: 6 | M6: Bromley | N6: 6.06 | O6: 10.76 | P6: -4.7
A7: Burton Albion | B7: 10 | C7: 5.57 | D7: 10 | E7: 7.67 | F7: -2.1 | G7: 0 | H7: 4.43 | I7: 6 | M7: Burton Albion | N7: 5.57 | O7: 7.67 | P7: -2.1
A8: Cambridge United | B8: 11 | C8: 5.83 | D8: 9 | E8: 10.39 | F8: -4.56 | G8: 2 | H8: 5.17 | I8: 6 | M8: Cambridge United | N8: 5.83 | O8: 10.39 | P8: -4.56
A9: Doncaster Rovers | B9: 6 | C9: 9.39 | D9: 9 | E9: 6.69 | F9: 2.7 | G9: -3 | H9: -3.39 | I9: 6 | M9: Doncaster Rovers | N9: 9.39 | O9: 6.69 | P9: 2.7
A10: Huddersfield Town | B10: 10 | C10: 11.04 | D10: 4 | E10: 6.25 | F10: 4.79 | G10: 6 | H10: -1.04 | I10: 6 | M10: Huddersfield Town | N10: 11.04 | O10: 6.25 | P10: 4.79
A11: Leicester City | B11: 8 | C11: 7.58 | D11: 10 | E11: 9.29 | F11: -1.71 | G11: -2 | H11: 0.42 | I11: 6 | M11: Leicester City | N11: 7.58 | O11: 9.29 | P11: -1.71
A12: Leyton Orient | B12: 12 | C12: 6.74 | D12: 9 | E12: 10.43 | F12: -3.69 | G12: 3 | H12: 5.26 | I12: 6 | M12: Leyton Orient | N12: 6.74 | O12: 10.43 | P12: -3.69
A13: Luton Town | B13: 12 | C13: 9.35 | D13: 13 | E13: 6.45 | F13: 2.9 | G13: -1 | H13: 2.65 | I13: 6 | M13: Luton Town | N13: 9.35 | O13: 6.45 | P13: 2.9
... A25: Wycombe Wanderers | B25: 10 | C25: 7.19 | D25: 14 | E25: 9.56 | F25: -2.37 | G25: -4 | H25: 2.81 | I25: 6 | M25: Wycombe Wanderers | N25: 7.19 | O25: 9.56 | P25: -2.37
A26: (blank) | M26: Grand Total | N26: 202.35 | O26: 202.35 | P26: 0
